#砦。入口は描画者側（ローカル-Z）を向く
execute as @e[tag=DuskArmorStand1,scores={Fortress=0}] at @s run fill ^-2 ^ ^1 ^-2 ^ ^-1 minecraft:cyan_glazed_terracotta keep
execute as @e[tag=DuskArmorStand1,scores={Fortress=0}] at @s run fill ^-1 ^ ^2 ^1 ^ ^2 minecraft:cyan_glazed_terracotta keep
execute as @e[tag=DuskArmorStand1,scores={Fortress=0}] at @s run fill ^2 ^ ^1 ^2 ^ ^-1 minecraft:cyan_glazed_terracotta keep
execute as @e[tag=DuskArmorStand1,scores={Fortress=0}] at @s run fill ^1 ^ ^-2 ^-1 ^ ^-2 minecraft:cyan_glazed_terracotta keep
execute as @e[tag=DuskArmorStand1,scores={Fortress=0}] at @s run fill ^-1 ^ ^1 ^1 ^ ^-1 minecraft:cyan_glazed_terracotta keep
execute as @e[tag=DuskArmorStand1,scores={Fortress=0}] at @s run fill ^-2 ^3 ^1 ^-2 ^1 ^-1 minecraft:cyan_glazed_terracotta keep
execute as @e[tag=DuskArmorStand1,scores={Fortress=0}] at @s run fill ^-1 ^3 ^2 ^1 ^1 ^2 minecraft:cyan_glazed_terracotta keep
execute as @e[tag=DuskArmorStand1,scores={Fortress=0}] at @s run fill ^2 ^3 ^1 ^2 ^1 ^-1 minecraft:cyan_glazed_terracotta keep
execute as @e[tag=DuskArmorStand1,scores={Fortress=0}] at @s run fill ^1 ^3 ^-2 ^1 ^1 ^-2 minecraft:cyan_glazed_terracotta keep
execute as @e[tag=DuskArmorStand1,scores={Fortress=0}] at @s run fill ^ ^3 ^-2 ^ ^3 ^-2 minecraft:cyan_glazed_terracotta keep
execute as @e[tag=DuskArmorStand1,scores={Fortress=0}] at @s run fill ^-1 ^3 ^-2 ^-1 ^1 ^-2 minecraft:cyan_glazed_terracotta keep
execute as @e[tag=DuskArmorStand1,scores={Fortress=0}] at @s run fill ^-3 ^4 ^1 ^-3 ^4 ^-1 minecraft:cyan_glazed_terracotta keep
execute as @e[tag=DuskArmorStand1,scores={Fortress=0}] at @s run fill ^-2 ^4 ^2 ^-2 ^4 ^2 minecraft:cyan_glazed_terracotta keep
execute as @e[tag=DuskArmorStand1,scores={Fortress=0}] at @s run fill ^-1 ^4 ^3 ^1 ^4 ^3 minecraft:cyan_glazed_terracotta keep
execute as @e[tag=DuskArmorStand1,scores={Fortress=0}] at @s run fill ^2 ^4 ^2 ^2 ^4 ^2 minecraft:cyan_glazed_terracotta keep
execute as @e[tag=DuskArmorStand1,scores={Fortress=0}] at @s run fill ^3 ^4 ^1 ^3 ^4 ^-1 minecraft:cyan_glazed_terracotta keep
execute as @e[tag=DuskArmorStand1,scores={Fortress=0}] at @s run fill ^2 ^4 ^-2 ^2 ^4 ^-2 minecraft:cyan_glazed_terracotta keep
execute as @e[tag=DuskArmorStand1,scores={Fortress=0}] at @s run fill ^-1 ^4 ^-3 ^1 ^4 ^-3 minecraft:cyan_glazed_terracotta keep
execute as @e[tag=DuskArmorStand1,scores={Fortress=0}] at @s run fill ^-2 ^4 ^1 ^2 ^4 ^1 minecraft:cyan_glazed_terracotta keep
execute as @e[tag=DuskArmorStand1,scores={Fortress=0}] at @s run fill ^-2 ^4 ^ ^-1 ^4 ^ minecraft:cyan_glazed_terracotta keep
execute as @e[tag=DuskArmorStand1,scores={Fortress=0}] at @s run fill ^1 ^4 ^ ^2 ^4 ^ minecraft:cyan_glazed_terracotta keep
execute as @e[tag=DuskArmorStand1,scores={Fortress=0}] at @s run fill ^-2 ^4 ^-1 ^2 ^4 ^-1 minecraft:cyan_glazed_terracotta keep
execute as @e[tag=DuskArmorStand1,scores={Fortress=0}] at @s run fill ^-1 ^4 ^2 ^1 ^4 ^2 minecraft:cyan_glazed_terracotta keep
execute as @e[tag=DuskArmorStand1,scores={Fortress=0}] at @s run fill ^-1 ^4 ^-2 ^1 ^4 ^-2 minecraft:cyan_glazed_terracotta keep
execute as @e[tag=DuskArmorStand1,scores={Fortress=0}] at @s run fill ^-2 ^4 ^-2 ^-2 ^4 ^-2 minecraft:cyan_glazed_terracotta keep
execute as @e[tag=DuskArmorStand1,scores={Fortress=0}] at @s run fill ^1 ^5 ^3 ^-1 ^5 ^3 minecraft:warped_fence keep
execute as @e[tag=DuskArmorStand1,scores={Fortress=0}] at @s run fill ^-1 ^5 ^2 ^-2 ^5 ^2 minecraft:warped_fence keep
execute as @e[tag=DuskArmorStand1,scores={Fortress=0}] at @s run fill ^-2 ^5 ^1 ^-3 ^5 ^1 minecraft:warped_fence keep
execute as @e[tag=DuskArmorStand1,scores={Fortress=0}] at @s run fill ^-3 ^5 ^1 ^-3 ^5 ^-1 minecraft:warped_fence keep
execute as @e[tag=DuskArmorStand1,scores={Fortress=0}] at @s run fill ^-3 ^5 ^-1 ^-2 ^5 ^-1 minecraft:warped_fence keep
execute as @e[tag=DuskArmorStand1,scores={Fortress=0}] at @s run fill ^-2 ^5 ^-2 ^-1 ^5 ^-2 minecraft:warped_fence keep
execute as @e[tag=DuskArmorStand1,scores={Fortress=0}] at @s run fill ^-1 ^5 ^-3 ^1 ^5 ^-3 minecraft:warped_fence keep
execute as @e[tag=DuskArmorStand1,scores={Fortress=0}] at @s run fill ^1 ^5 ^-2 ^2 ^5 ^-2 minecraft:warped_fence keep
execute as @e[tag=DuskArmorStand1,scores={Fortress=0}] at @s run fill ^3 ^5 ^-1 ^3 ^5 ^1 minecraft:warped_fence keep
execute as @e[tag=DuskArmorStand1,scores={Fortress=0}] at @s run fill ^-2 ^5 ^1 ^-2 ^5 ^2 minecraft:warped_fence keep
execute as @e[tag=DuskArmorStand1,scores={Fortress=0}] at @s run fill ^-1 ^5 ^2 ^-1 ^5 ^3 minecraft:warped_fence keep
execute as @e[tag=DuskArmorStand1,scores={Fortress=0}] at @s run fill ^ ^1 ^ ^ ^4 ^ minecraft:ladder keep

#画中人を2体召喚
execute as @e[tag=DuskArmorStand1,scores={Fortress=0},team=Blue] at @s run summon minecraft:skeleton ^-1 ^5 ^1 {Team:'Blue',Health:30f,Tags:['gatyuzin','DuskNew','MTentity'],CustomName:{text:'画中人'},equipment:{head:{id:'minecraft:leather_helmet',count:1,components:{'minecraft:dyed_color':16711680}},mainhand:{id:'minecraft:bow',count:1,components:{'minecraft:enchantments':{'minecraft:power':3}}}},attributes:[{id:'minecraft:max_health',base:30.0}]}
execute as @e[tag=DuskArmorStand1,scores={Fortress=0},team=Blue] at @s run summon minecraft:skeleton ^1 ^5 ^1 {Team:'Blue',Health:30f,Tags:['gatyuzin','DuskNew','MTentity'],CustomName:{text:'画中人'},equipment:{head:{id:'minecraft:leather_helmet',count:1,components:{'minecraft:dyed_color':16711680}},mainhand:{id:'minecraft:bow',count:1,components:{'minecraft:enchantments':{'minecraft:power':3}}}},attributes:[{id:'minecraft:max_health',base:30.0}]}
execute as @e[tag=DuskArmorStand1,scores={Fortress=0},team=Red] at @s run summon minecraft:skeleton ^-1 ^5 ^1 {Team:'Red',Health:30f,Tags:['gatyuzin','DuskNew','MTentity'],CustomName:{text:'画中人'},equipment:{head:{id:'minecraft:leather_helmet',count:1,components:{'minecraft:dyed_color':16711680}},mainhand:{id:'minecraft:bow',count:1,components:{'minecraft:enchantments':{'minecraft:power':3}}}},attributes:[{id:'minecraft:max_health',base:30.0}]}
execute as @e[tag=DuskArmorStand1,scores={Fortress=0},team=Red] at @s run summon minecraft:skeleton ^1 ^5 ^1 {Team:'Red',Health:30f,Tags:['gatyuzin','DuskNew','MTentity'],CustomName:{text:'画中人'},equipment:{head:{id:'minecraft:leather_helmet',count:1,components:{'minecraft:dyed_color':16711680}},mainhand:{id:'minecraft:bow',count:1,components:{'minecraft:enchantments':{'minecraft:power':3}}}},attributes:[{id:'minecraft:max_health',base:30.0}]}
scoreboard players operation @e[tag=DuskNew] DuskOwner = @s DuskOwner
scoreboard players set @e[tag=DuskNew] rabbit 0
tag @e[tag=DuskNew] remove DuskNew
scoreboard players set @e[tag=DuskArmorStand1,scores={Fortress=0}] Fortress 1
